[2022-12-25 20:41:52] [INFO    ] discord.client: logging in using static token
[2022-12-25 20:41:53] [INFO    ] discord.gateway: Shard ID None has connected to Gateway (Session ID: 36b5f78affe7ebc4129bfc091daf2dd4).
[2022-12-25 20:41:55] [ERROR   ] discord.client: Ignoring exception in on_command_completion
Traceback (most recent call last):
  File "/Users/a../repos/discordbot/user_configuration.py", line 206, in getUserConfig
    return j[user_option]
KeyError: 'usage'

During handling of the above exception, another exception occurred:

Traceback (most recent call last):
  File "/opt/homebrew/lib/python3.10/site-packages/discord/client.py", line 409, in _run_event
    await coro(*args, **kwargs)
  File "/Users/a../repos/discordbot/discord_bot_dec20.py", line 452, in on_command_completion
    user_configuration.incrementUserConfig(str(userid))
  File "/Users/a../repos/discordbot/user_configuration.py", line 300, in incrementUserConfig
    old_usage = getUserConfig(user,'usage')
  File "/Users/a../repos/discordbot/user_configuration.py", line 211, in getUserConfig
    return getUserConfig(__DEFAULT_USER__)[user_option]
TypeError: 'int' object is not subscriptable
[2022-12-25 20:42:14] [ERROR   ] discord.client: Ignoring exception in on_command_completion
Traceback (most recent call last):
  File "/Users/a../repos/discordbot/user_configuration.py", line 206, in getUserConfig
    return j[user_option]
KeyError: 'usage'

During handling of the above exception, another exception occurred:

Traceback (most recent call last):
  File "/opt/homebrew/lib/python3.10/site-packages/discord/client.py", line 409, in _run_event
    await coro(*args, **kwargs)
  File "/Users/a../repos/discordbot/discord_bot_dec20.py", line 452, in on_command_completion
    user_configuration.incrementUserConfig(str(userid))
  File "/Users/a../repos/discordbot/user_configuration.py", line 300, in incrementUserConfig
    old_usage = getUserConfig(user,'usage')
  File "/Users/a../repos/discordbot/user_configuration.py", line 211, in getUserConfig
    return getUserConfig(__DEFAULT_USER__)[user_option]
TypeError: 'int' object is not subscriptable
[2022-12-25 20:42:48] [ERROR   ] discord.client: Ignoring exception in on_command_completion
Traceback (most recent call last):
  File "/Users/a../repos/discordbot/user_configuration.py", line 206, in getUserConfig
    return j[user_option]
KeyError: 'usage'

During handling of the above exception, another exception occurred:

Traceback (most recent call last):
  File "/opt/homebrew/lib/python3.10/site-packages/discord/client.py", line 409, in _run_event
    await coro(*args, **kwargs)
  File "/Users/a../repos/discordbot/discord_bot_dec20.py", line 452, in on_command_completion
    user_configuration.incrementUserConfig(str(userid))
  File "/Users/a../repos/discordbot/user_configuration.py", line 300, in incrementUserConfig
    old_usage = getUserConfig(user,'usage')
  File "/Users/a../repos/discordbot/user_configuration.py", line 211, in getUserConfig
    return getUserConfig(__DEFAULT_USER__)[user_option]
TypeError: 'int' object is not subscriptable
[2022-12-25 20:42:51] [ERROR   ] discord.client: Ignoring exception in on_command_completion
Traceback (most recent call last):
  File "/Users/a../repos/discordbot/user_configuration.py", line 206, in getUserConfig
    return j[user_option]
KeyError: 'usage'

During handling of the above exception, another exception occurred:

Traceback (most recent call last):
  File "/opt/homebrew/lib/python3.10/site-packages/discord/client.py", line 409, in _run_event
    await coro(*args, **kwargs)
  File "/Users/a../repos/discordbot/discord_bot_dec20.py", line 452, in on_command_completion
    user_configuration.incrementUserConfig(str(userid))
  File "/Users/a../repos/discordbot/user_configuration.py", line 300, in incrementUserConfig
    old_usage = getUserConfig(user,'usage')
  File "/Users/a../repos/discordbot/user_configuration.py", line 211, in getUserConfig
    return getUserConfig(__DEFAULT_USER__)[user_option]
TypeError: 'int' object is not subscriptable
[2022-12-25 20:52:58] [INFO    ] discord.gateway: Shard ID None session has been invalidated.
[2022-12-25 20:53:04] [INFO    ] discord.gateway: Shard ID None has connected to Gateway (Session ID: 6c579abd3ea73354249729f3f9b0138f).
[2022-12-25 22:00:36] [INFO    ] discord.gateway: Shard ID None has successfully RESUMED session 6c579abd3ea73354249729f3f9b0138f.
[2022-12-25 22:12:29] [INFO    ] discord.gateway: Shard ID None has successfully RESUMED session 6c579abd3ea73354249729f3f9b0138f.
[2022-12-25 22:30:15] [INFO    ] discord.gateway: Shard ID None session has been invalidated.
[2022-12-25 22:30:21] [INFO    ] discord.gateway: Shard ID None has connected to Gateway (Session ID: 2641b28558faa942278a25a54cf772df).
[2022-12-25 22:34:08] [INFO    ] discord.gateway: Shard ID None session has been invalidated.
[2022-12-25 22:34:13] [INFO    ] discord.gateway: Shard ID None has connected to Gateway (Session ID: 313a2887387084c8174f143f959ff434).
[2022-12-25 22:35:45] [ERROR   ] discord.client: Attempting a reconnect in 1.84s
Traceback (most recent call last):
  File "/opt/homebrew/lib/python3.10/site-packages/discord/client.py", line 627, in connect
    await self.ws.poll_event()
  File "/opt/homebrew/lib/python3.10/site-packages/discord/gateway.py", line 646, in poll_event
    raise ConnectionClosed(self.socket, shard_id=self.shard_id, code=code) from None
discord.errors.ConnectionClosed: Shard ID None WebSocket closed with 1000
[2022-12-25 22:35:47] [INFO    ] discord.gateway: Shard ID None has successfully RESUMED session 313a2887387084c8174f143f959ff434.
[2022-12-25 22:55:09] [ERROR   ] discord.client: Ignoring exception in on_command_completion
Traceback (most recent call last):
  File "/Users/a../repos/discordbot/user_configuration.py", line 206, in getUserConfig
    }
KeyError: 'usage'

During handling of the above exception, another exception occurred:

Traceback (most recent call last):
  File "/opt/homebrew/lib/python3.10/site-packages/discord/client.py", line 409, in _run_event
    await coro(*args, **kwargs)
  File "/Users/a../repos/discordbot/discord_bot_dec20.py", line 452, in on_command_completion
    #     if message.author == bot.user: # Prevent loops
  File "/Users/a../repos/discordbot/user_configuration.py", line 300, in incrementUserConfig
    #         print(viewFullUserConfig(user=current_user))
  File "/Users/a../repos/discordbot/user_configuration.py", line 211, in getUserConfig
    }
TypeError: 'int' object is not subscriptable
[2022-12-25 22:55:25] [ERROR   ] discord.client: Ignoring exception in on_command_completion
Traceback (most recent call last):
  File "/Users/a../repos/discordbot/user_configuration.py", line 206, in getUserConfig
    }
KeyError: 'usage'

During handling of the above exception, another exception occurred:

Traceback (most recent call last):
  File "/opt/homebrew/lib/python3.10/site-packages/discord/client.py", line 409, in _run_event
    await coro(*args, **kwargs)
  File "/Users/a../repos/discordbot/discord_bot_dec20.py", line 452, in on_command_completion
    #     if message.author == bot.user: # Prevent loops
  File "/Users/a../repos/discordbot/user_configuration.py", line 300, in incrementUserConfig
    #         print(viewFullUserConfig(user=current_user))
  File "/Users/a../repos/discordbot/user_configuration.py", line 211, in getUserConfig
    }
TypeError: 'int' object is not subscriptable
